{
 "cells": [
  {
   "cell_type": "code",
   "execution_count": 1,
   "id": "accepted-communications",
   "metadata": {},
   "outputs": [],
   "source": [
    "import pandas as pd\n",
    "import joblib\n",
    "from fydjob.Database import Database"
   ]
  },
  {
   "cell_type": "code",
   "execution_count": 2,
   "id": "perfect-domestic",
   "metadata": {},
   "outputs": [],
   "source": [
    "from fydjob.utils import lemmatize_words, remove_stopwords, join_strings"
   ]
  },
  {
   "cell_type": "code",
   "execution_count": null,
   "id": "encouraging-radar",
   "metadata": {},
   "outputs": [
    {
     "name": "stderr",
     "output_type": "stream",
     "text": [
      "ERROR:root:Internal Python error in the inspect module.\n",
      "Below is the traceback from this internal error.\n",
      "\n",
      "ERROR:root:Internal Python error in the inspect module.\n",
      "Below is the traceback from this internal error.\n",
      "\n"
     ]
    },
    {
     "name": "stdout",
     "output_type": "stream",
     "text": [
      "Traceback (most recent call last):\n",
      "  File \"/home/vlud/.pyenv/versions/3.8.6/envs/fydjob/lib/python3.8/site-packages/IPython/core/interactiveshell.py\", line 3437, in run_code\n",
      "    exec(code_obj, self.user_global_ns, self.user_ns)\n",
      "  File \"<ipython-input-3-b4a80be8d8cb>\", line 2, in <module>\n",
      "    df = db.to_frame()\n",
      "  File \"/home/vlud/code/OWNER_vlad/find-your-dream-job/fydjob/Database.py\", line 151, in to_frame\n",
      "    result = cur.execute(sql).fetchall()\n",
      "KeyboardInterrupt\n",
      "\n",
      "During handling of the above exception, another exception occurred:\n",
      "\n",
      "Traceback (most recent call last):\n",
      "  File \"/home/vlud/.pyenv/versions/3.8.6/envs/fydjob/lib/python3.8/site-packages/IPython/core/interactiveshell.py\", line 2061, in showtraceback\n",
      "    stb = value._render_traceback_()\n",
      "AttributeError: 'KeyboardInterrupt' object has no attribute '_render_traceback_'\n",
      "\n",
      "During handling of the above exception, another exception occurred:\n",
      "\n",
      "Traceback (most recent call last):\n",
      "  File \"/home/vlud/.pyenv/versions/3.8.6/envs/fydjob/lib/python3.8/site-packages/IPython/core/ultratb.py\", line 1101, in get_records\n",
      "    return _fixed_getinnerframes(etb, number_of_lines_of_context, tb_offset)\n",
      "  File \"/home/vlud/.pyenv/versions/3.8.6/envs/fydjob/lib/python3.8/site-packages/IPython/core/ultratb.py\", line 248, in wrapped\n",
      "    return f(*args, **kwargs)\n",
      "  File \"/home/vlud/.pyenv/versions/3.8.6/envs/fydjob/lib/python3.8/site-packages/IPython/core/ultratb.py\", line 281, in _fixed_getinnerframes\n",
      "    records = fix_frame_records_filenames(inspect.getinnerframes(etb, context))\n",
      "  File \"/home/vlud/.pyenv/versions/3.8.6/lib/python3.8/inspect.py\", line 1503, in getinnerframes\n",
      "    frameinfo = (tb.tb_frame,) + getframeinfo(tb, context)\n",
      "  File \"/home/vlud/.pyenv/versions/3.8.6/lib/python3.8/inspect.py\", line 1461, in getframeinfo\n",
      "    filename = getsourcefile(frame) or getfile(frame)\n",
      "  File \"/home/vlud/.pyenv/versions/3.8.6/lib/python3.8/inspect.py\", line 708, in getsourcefile\n",
      "    if getattr(getmodule(object, filename), '__loader__', None) is not None:\n",
      "  File \"/home/vlud/.pyenv/versions/3.8.6/lib/python3.8/inspect.py\", line 751, in getmodule\n",
      "    f = getabsfile(module)\n",
      "  File \"/home/vlud/.pyenv/versions/3.8.6/lib/python3.8/inspect.py\", line 720, in getabsfile\n",
      "    _filename = getsourcefile(object) or getfile(object)\n",
      "  File \"/home/vlud/.pyenv/versions/3.8.6/lib/python3.8/inspect.py\", line 705, in getsourcefile\n",
      "    if os.path.exists(filename):\n",
      "  File \"/home/vlud/.pyenv/versions/3.8.6/lib/python3.8/genericpath.py\", line 18, in exists\n",
      "    try:\n",
      "KeyboardInterrupt\n",
      "Traceback (most recent call last):\n",
      "  File \"/home/vlud/.pyenv/versions/3.8.6/envs/fydjob/lib/python3.8/site-packages/IPython/core/interactiveshell.py\", line 3437, in run_code\n",
      "    exec(code_obj, self.user_global_ns, self.user_ns)\n",
      "  File \"<ipython-input-3-b4a80be8d8cb>\", line 2, in <module>\n",
      "    df = db.to_frame()\n",
      "  File \"/home/vlud/code/OWNER_vlad/find-your-dream-job/fydjob/Database.py\", line 151, in to_frame\n",
      "    result = cur.execute(sql).fetchall()\n",
      "KeyboardInterrupt\n",
      "\n",
      "During handling of the above exception, another exception occurred:\n",
      "\n",
      "Traceback (most recent call last):\n",
      "  File \"/home/vlud/.pyenv/versions/3.8.6/envs/fydjob/lib/python3.8/site-packages/IPython/core/interactiveshell.py\", line 2061, in showtraceback\n",
      "    stb = value._render_traceback_()\n",
      "AttributeError: 'KeyboardInterrupt' object has no attribute '_render_traceback_'\n",
      "\n",
      "During handling of the above exception, another exception occurred:\n",
      "\n",
      "Traceback (most recent call last):\n",
      "  File \"/home/vlud/.pyenv/versions/3.8.6/envs/fydjob/lib/python3.8/site-packages/IPython/core/interactiveshell.py\", line 3357, in run_ast_nodes\n",
      "    if (await self.run_code(code, result,  async_=asy)):\n",
      "  File \"/home/vlud/.pyenv/versions/3.8.6/envs/fydjob/lib/python3.8/site-packages/IPython/core/interactiveshell.py\", line 3454, in run_code\n",
      "    self.showtraceback(running_compiled_code=True)\n",
      "  File \"/home/vlud/.pyenv/versions/3.8.6/envs/fydjob/lib/python3.8/site-packages/IPython/core/interactiveshell.py\", line 2063, in showtraceback\n",
      "    stb = self.InteractiveTB.structured_traceback(etype,\n",
      "  File \"/home/vlud/.pyenv/versions/3.8.6/envs/fydjob/lib/python3.8/site-packages/IPython/core/ultratb.py\", line 1367, in structured_traceback\n",
      "    return FormattedTB.structured_traceback(\n",
      "  File \"/home/vlud/.pyenv/versions/3.8.6/envs/fydjob/lib/python3.8/site-packages/IPython/core/ultratb.py\", line 1267, in structured_traceback\n",
      "    return VerboseTB.structured_traceback(\n",
      "  File \"/home/vlud/.pyenv/versions/3.8.6/envs/fydjob/lib/python3.8/site-packages/IPython/core/ultratb.py\", line 1124, in structured_traceback\n",
      "    formatted_exception = self.format_exception_as_a_whole(etype, evalue, etb, number_of_lines_of_context,\n",
      "  File \"/home/vlud/.pyenv/versions/3.8.6/envs/fydjob/lib/python3.8/site-packages/IPython/core/ultratb.py\", line 1082, in format_exception_as_a_whole\n",
      "    last_unique, recursion_repeat = find_recursion(orig_etype, evalue, records)\n",
      "  File \"/home/vlud/.pyenv/versions/3.8.6/envs/fydjob/lib/python3.8/site-packages/IPython/core/ultratb.py\", line 382, in find_recursion\n",
      "    return len(records), 0\n",
      "TypeError: object of type 'NoneType' has no len()\n",
      "\n",
      "During handling of the above exception, another exception occurred:\n",
      "\n",
      "Traceback (most recent call last):\n",
      "  File \"/home/vlud/.pyenv/versions/3.8.6/envs/fydjob/lib/python3.8/site-packages/IPython/core/interactiveshell.py\", line 2061, in showtraceback\n",
      "    stb = value._render_traceback_()\n",
      "AttributeError: 'TypeError' object has no attribute '_render_traceback_'\n",
      "\n",
      "During handling of the above exception, another exception occurred:\n",
      "\n",
      "Traceback (most recent call last):\n",
      "  File \"/home/vlud/.pyenv/versions/3.8.6/envs/fydjob/lib/python3.8/site-packages/IPython/core/ultratb.py\", line 1101, in get_records\n",
      "    return _fixed_getinnerframes(etb, number_of_lines_of_context, tb_offset)\n",
      "  File \"/home/vlud/.pyenv/versions/3.8.6/envs/fydjob/lib/python3.8/site-packages/IPython/core/ultratb.py\", line 248, in wrapped\n",
      "    return f(*args, **kwargs)\n",
      "  File \"/home/vlud/.pyenv/versions/3.8.6/envs/fydjob/lib/python3.8/site-packages/IPython/core/ultratb.py\", line 281, in _fixed_getinnerframes\n",
      "    records = fix_frame_records_filenames(inspect.getinnerframes(etb, context))\n",
      "  File \"/home/vlud/.pyenv/versions/3.8.6/lib/python3.8/inspect.py\", line 1503, in getinnerframes\n",
      "    frameinfo = (tb.tb_frame,) + getframeinfo(tb, context)\n",
      "  File \"/home/vlud/.pyenv/versions/3.8.6/lib/python3.8/inspect.py\", line 1461, in getframeinfo\n",
      "    filename = getsourcefile(frame) or getfile(frame)\n",
      "  File \"/home/vlud/.pyenv/versions/3.8.6/lib/python3.8/inspect.py\", line 708, in getsourcefile\n",
      "    if getattr(getmodule(object, filename), '__loader__', None) is not None:\n",
      "  File \"/home/vlud/.pyenv/versions/3.8.6/lib/python3.8/inspect.py\", line 754, in getmodule\n",
      "    os.path.realpath(f)] = module.__name__\n",
      "  File \"/home/vlud/.pyenv/versions/3.8.6/lib/python3.8/posixpath.py\", line 391, in realpath\n",
      "    path, ok = _joinrealpath(filename[:0], filename, {})\n",
      "  File \"/home/vlud/.pyenv/versions/3.8.6/lib/python3.8/posixpath.py\", line 425, in _joinrealpath\n",
      "    if not islink(newpath):\n",
      "KeyboardInterrupt\n"
     ]
    },
    {
     "name": "stderr",
     "output_type": "stream",
     "text": [
      "ERROR:root:Internal Python error in the inspect module.\n",
      "Below is the traceback from this internal error.\n",
      "\n"
     ]
    },
    {
     "name": "stdout",
     "output_type": "stream",
     "text": [
      "Traceback (most recent call last):\n",
      "  File \"/home/vlud/.pyenv/versions/3.8.6/envs/fydjob/lib/python3.8/site-packages/IPython/core/interactiveshell.py\", line 3437, in run_code\n",
      "    exec(code_obj, self.user_global_ns, self.user_ns)\n",
      "  File \"<ipython-input-3-b4a80be8d8cb>\", line 2, in <module>\n",
      "    df = db.to_frame()\n",
      "  File \"/home/vlud/code/OWNER_vlad/find-your-dream-job/fydjob/Database.py\", line 151, in to_frame\n",
      "    result = cur.execute(sql).fetchall()\n",
      "KeyboardInterrupt\n",
      "\n",
      "During handling of the above exception, another exception occurred:\n",
      "\n",
      "Traceback (most recent call last):\n",
      "  File \"/home/vlud/.pyenv/versions/3.8.6/envs/fydjob/lib/python3.8/site-packages/IPython/core/interactiveshell.py\", line 2061, in showtraceback\n",
      "    stb = value._render_traceback_()\n",
      "AttributeError: 'KeyboardInterrupt' object has no attribute '_render_traceback_'\n",
      "\n",
      "During handling of the above exception, another exception occurred:\n",
      "\n",
      "Traceback (most recent call last):\n",
      "  File \"/home/vlud/.pyenv/versions/3.8.6/envs/fydjob/lib/python3.8/site-packages/IPython/core/interactiveshell.py\", line 3357, in run_ast_nodes\n",
      "    if (await self.run_code(code, result,  async_=asy)):\n",
      "  File \"/home/vlud/.pyenv/versions/3.8.6/envs/fydjob/lib/python3.8/site-packages/IPython/core/interactiveshell.py\", line 3454, in run_code\n",
      "    self.showtraceback(running_compiled_code=True)\n",
      "  File \"/home/vlud/.pyenv/versions/3.8.6/envs/fydjob/lib/python3.8/site-packages/IPython/core/interactiveshell.py\", line 2063, in showtraceback\n",
      "    stb = self.InteractiveTB.structured_traceback(etype,\n",
      "  File \"/home/vlud/.pyenv/versions/3.8.6/envs/fydjob/lib/python3.8/site-packages/IPython/core/ultratb.py\", line 1367, in structured_traceback\n",
      "    return FormattedTB.structured_traceback(\n",
      "  File \"/home/vlud/.pyenv/versions/3.8.6/envs/fydjob/lib/python3.8/site-packages/IPython/core/ultratb.py\", line 1267, in structured_traceback\n",
      "    return VerboseTB.structured_traceback(\n",
      "  File \"/home/vlud/.pyenv/versions/3.8.6/envs/fydjob/lib/python3.8/site-packages/IPython/core/ultratb.py\", line 1124, in structured_traceback\n",
      "    formatted_exception = self.format_exception_as_a_whole(etype, evalue, etb, number_of_lines_of_context,\n",
      "  File \"/home/vlud/.pyenv/versions/3.8.6/envs/fydjob/lib/python3.8/site-packages/IPython/core/ultratb.py\", line 1082, in format_exception_as_a_whole\n",
      "    last_unique, recursion_repeat = find_recursion(orig_etype, evalue, records)\n",
      "  File \"/home/vlud/.pyenv/versions/3.8.6/envs/fydjob/lib/python3.8/site-packages/IPython/core/ultratb.py\", line 382, in find_recursion\n",
      "    return len(records), 0\n",
      "TypeError: object of type 'NoneType' has no len()\n",
      "\n",
      "During handling of the above exception, another exception occurred:\n",
      "\n",
      "Traceback (most recent call last):\n",
      "  File \"/home/vlud/.pyenv/versions/3.8.6/envs/fydjob/lib/python3.8/site-packages/IPython/core/interactiveshell.py\", line 2061, in showtraceback\n",
      "    stb = value._render_traceback_()\n",
      "AttributeError: 'TypeError' object has no attribute '_render_traceback_'\n",
      "\n",
      "During handling of the above exception, another exception occurred:\n",
      "\n",
      "Traceback (most recent call last):\n",
      "  File \"/home/vlud/.pyenv/versions/3.8.6/envs/fydjob/lib/python3.8/site-packages/IPython/core/interactiveshell.py\", line 2940, in _run_cell\n",
      "    return runner(coro)\n",
      "  File \"/home/vlud/.pyenv/versions/3.8.6/envs/fydjob/lib/python3.8/site-packages/IPython/core/async_helpers.py\", line 68, in _pseudo_sync_runner\n",
      "    coro.send(None)\n",
      "  File \"/home/vlud/.pyenv/versions/3.8.6/envs/fydjob/lib/python3.8/site-packages/IPython/core/interactiveshell.py\", line 3165, in run_cell_async\n",
      "    has_raised = await self.run_ast_nodes(code_ast.body, cell_name,\n",
      "  File \"/home/vlud/.pyenv/versions/3.8.6/envs/fydjob/lib/python3.8/site-packages/IPython/core/interactiveshell.py\", line 3376, in run_ast_nodes\n",
      "    self.showtraceback()\n",
      "  File \"/home/vlud/.pyenv/versions/3.8.6/envs/fydjob/lib/python3.8/site-packages/IPython/core/interactiveshell.py\", line 2063, in showtraceback\n",
      "    stb = self.InteractiveTB.structured_traceback(etype,\n",
      "  File \"/home/vlud/.pyenv/versions/3.8.6/envs/fydjob/lib/python3.8/site-packages/IPython/core/ultratb.py\", line 1367, in structured_traceback\n",
      "    return FormattedTB.structured_traceback(\n",
      "  File \"/home/vlud/.pyenv/versions/3.8.6/envs/fydjob/lib/python3.8/site-packages/IPython/core/ultratb.py\", line 1267, in structured_traceback\n",
      "    return VerboseTB.structured_traceback(\n",
      "  File \"/home/vlud/.pyenv/versions/3.8.6/envs/fydjob/lib/python3.8/site-packages/IPython/core/ultratb.py\", line 1142, in structured_traceback\n",
      "    formatted_exceptions += self.format_exception_as_a_whole(etype, evalue, etb, lines_of_context,\n",
      "  File \"/home/vlud/.pyenv/versions/3.8.6/envs/fydjob/lib/python3.8/site-packages/IPython/core/ultratb.py\", line 1082, in format_exception_as_a_whole\n",
      "    last_unique, recursion_repeat = find_recursion(orig_etype, evalue, records)\n",
      "  File \"/home/vlud/.pyenv/versions/3.8.6/envs/fydjob/lib/python3.8/site-packages/IPython/core/ultratb.py\", line 382, in find_recursion\n",
      "    return len(records), 0\n",
      "TypeError: object of type 'NoneType' has no len()\n",
      "\n",
      "During handling of the above exception, another exception occurred:\n",
      "\n",
      "Traceback (most recent call last):\n",
      "  File \"/home/vlud/.pyenv/versions/3.8.6/envs/fydjob/lib/python3.8/site-packages/IPython/core/interactiveshell.py\", line 2061, in showtraceback\n",
      "    stb = value._render_traceback_()\n",
      "AttributeError: 'TypeError' object has no attribute '_render_traceback_'\n",
      "\n",
      "During handling of the above exception, another exception occurred:\n",
      "\n",
      "Traceback (most recent call last):\n",
      "  File \"/home/vlud/.pyenv/versions/3.8.6/envs/fydjob/lib/python3.8/site-packages/IPython/core/ultratb.py\", line 1101, in get_records\n",
      "    return _fixed_getinnerframes(etb, number_of_lines_of_context, tb_offset)\n",
      "  File \"/home/vlud/.pyenv/versions/3.8.6/envs/fydjob/lib/python3.8/site-packages/IPython/core/ultratb.py\", line 248, in wrapped\n",
      "    return f(*args, **kwargs)\n",
      "  File \"/home/vlud/.pyenv/versions/3.8.6/envs/fydjob/lib/python3.8/site-packages/IPython/core/ultratb.py\", line 281, in _fixed_getinnerframes\n",
      "    records = fix_frame_records_filenames(inspect.getinnerframes(etb, context))\n",
      "  File \"/home/vlud/.pyenv/versions/3.8.6/lib/python3.8/inspect.py\", line 1503, in getinnerframes\n",
      "    frameinfo = (tb.tb_frame,) + getframeinfo(tb, context)\n",
      "  File \"/home/vlud/.pyenv/versions/3.8.6/lib/python3.8/inspect.py\", line 1461, in getframeinfo\n",
      "    filename = getsourcefile(frame) or getfile(frame)\n",
      "  File \"/home/vlud/.pyenv/versions/3.8.6/lib/python3.8/inspect.py\", line 708, in getsourcefile\n",
      "    if getattr(getmodule(object, filename), '__loader__', None) is not None:\n",
      "  File \"/home/vlud/.pyenv/versions/3.8.6/lib/python3.8/inspect.py\", line 754, in getmodule\n",
      "    os.path.realpath(f)] = module.__name__\n",
      "  File \"/home/vlud/.pyenv/versions/3.8.6/lib/python3.8/posixpath.py\", line 391, in realpath\n",
      "    path, ok = _joinrealpath(filename[:0], filename, {})\n",
      "  File \"/home/vlud/.pyenv/versions/3.8.6/lib/python3.8/posixpath.py\", line 425, in _joinrealpath\n",
      "    if not islink(newpath):\n",
      "  File \"/home/vlud/.pyenv/versions/3.8.6/lib/python3.8/posixpath.py\", line 167, in islink\n",
      "    st = os.lstat(path)\n",
      "KeyboardInterrupt\n"
     ]
    }
   ],
   "source": [
    "db = Database()\n",
    "df = db.to_frame()"
   ]
  },
  {
   "cell_type": "markdown",
   "id": "stable-capacity",
   "metadata": {},
   "source": [
    "df = joblib.load('output/indeed_proc/processed_data.joblib')"
   ]
  },
  {
   "cell_type": "code",
   "execution_count": null,
   "id": "increasing-steam",
   "metadata": {},
   "outputs": [],
   "source": [
    "df.head()"
   ]
  },
  {
   "cell_type": "code",
   "execution_count": null,
   "id": "casual-sound",
   "metadata": {},
   "outputs": [],
   "source": [
    "df.shape"
   ]
  },
  {
   "cell_type": "code",
   "execution_count": null,
   "id": "binary-seventh",
   "metadata": {},
   "outputs": [],
   "source": [
    "df['clean'] = df.job_text_tokenized.apply(join_strings).apply(lemmatize_words).apply(remove_stopwords)"
   ]
  },
  {
   "cell_type": "code",
   "execution_count": null,
   "id": "sealed-halloween",
   "metadata": {},
   "outputs": [],
   "source": []
  }
 ],
 "metadata": {
  "kernelspec": {
   "display_name": "Python 3",
   "language": "python",
   "name": "python3"
  },
  "language_info": {
   "codemirror_mode": {
    "name": "ipython",
    "version": 3
   },
   "file_extension": ".py",
   "mimetype": "text/x-python",
   "name": "python",
   "nbconvert_exporter": "python",
   "pygments_lexer": "ipython3",
   "version": "3.8.6"
  }
 },
 "nbformat": 4,
 "nbformat_minor": 5
}
